#VRML_SIM R2020b utf8
WorldInfo {
  basicTimeStep 64
  FPS 120
  coordinateSystem "NUE"
  contactProperties [
    ContactProperties {
      softCFM 0.0001
    }
  ]
}
Viewpoint {
  orientation 0.6013527779304436 0.7907970928783085 0.1140824016689448 5.763790674639816
  position -0.2857473420373825 0.6587990548203886 0.7692003237548548
}
TexturedBackground {
}
TexturedBackgroundLight {
}
RectangleArena {
  translation 0 0.005 0
  floorSize 1.5 1.5
  wallHeight 0.2
}
DEF Automat Robot {
  translation 0 0.01 0
  rotation 1 0 0 0
  children [
    DEF unvisible_box_1 Solid {
      translation 0.118 0 0.24
      children [
        Shape {
          appearance PBRAppearance {
            transparency 1
            metalness 0
          }
          geometry DEF unvisible_box_1 Box {
            size 0.01 0.02 1.1
          }
        }
      ]
      name "solid(33)"
      boundingObject USE unvisible_box_1
    }
    DEF unvisible_box_2 Solid {
      translation 0.132 0 0.24
      children [
        Shape {
          appearance PBRAppearance {
            transparency 1
            metalness 0
          }
          geometry DEF unvisible_box_1 Box {
            size 0.01 0.02 1.1
          }
        }
      ]
      name "solid(34)"
      boundingObject USE unvisible_box_1
    }
    DEF point_light_2 PointLight {
      attenuation 0 0 1
      intensity 0.1
      location 0.15 0.3 -0.4
    }
    DEF piston_6 SliderJoint {
      jointParameters JointParameters {
      }
      device [
        LinearMotor {
          name "piston 6"
          maxVelocity 0.1
        }
      ]
      endPoint Solid {
        translation 0.075 0.275 -0.48
        children [
          Shape {
            appearance PBRAppearance {
              baseColor 0.4 0.4 0.4
              metalness 0
            }
            geometry DEF piston_6 Box {
              size 0.04 0.07 0.02
            }
          }
        ]
        name "solid(30)"
        boundingObject USE piston_6
      }
    }
    DEF piston_5 SliderJoint {
      jointParameters JointParameters {
      }
      device [
        LinearMotor {
          name "piston 5"
          maxVelocity 0.1
        }
      ]
      endPoint Solid {
        translation 0.005 0.275 -0.48
        children [
          Shape {
            appearance PBRAppearance {
              baseColor 0.4 0.4 0.4
              metalness 0
            }
            geometry DEF piston_5 Box {
              size 0.04 0.07 0.02
            }
          }
        ]
        name "solid(29)"
        boundingObject USE piston_5
      }
    }
    DEF piston_4 SliderJoint {
      jointParameters JointParameters {
      }
      device [
        LinearMotor {
          name "piston 4"
          maxVelocity 0.1
        }
      ]
      endPoint Solid {
        translation -0.065 0.275 -0.48
        children [
          Shape {
            appearance PBRAppearance {
              baseColor 0.4 0.4 0.4
              metalness 0
            }
            geometry DEF piston_4 Box {
              size 0.04 0.07 0.02
            }
          }
        ]
        name "solid(28)"
        boundingObject USE piston_4
      }
    }
    DEF piston_3 SliderJoint {
      jointParameters JointParameters {
      }
      device [
        LinearMotor {
          name "piston 3"
          maxVelocity 0.1
        }
      ]
      endPoint Solid {
        translation 0.075 0.375 -0.48
        rotation 5.662748247667581e-07 0.7071067811864341 0.7071067811864341 3.14159
        children [
          Shape {
            appearance PBRAppearance {
              baseColor 0.4 0.4 0.4
              metalness 0
            }
            geometry DEF piston_3 Box {
              size 0.04 0.02 0.07
            }
          }
        ]
        name "solid(27)"
        boundingObject USE piston_3
      }
    }
    DEF shelf_1 Solid {
      translation 0.005 0.325 -0.44
      rotation 0 0.7071062811861719 0.7071072811865696 3.14159
      children [
        Shape {
          appearance PBRAppearance {
            baseColor 0.2 0.2 0.2
            metalness 0
          }
          geometry DEF shelf_1 Box {
            size 0.2 0.124 0.02
          }
        }
      ]
      name "solid(19)"
      boundingObject USE shelf_1
    }
    DEF shelf_2 Solid {
      translation 0.005 0.225 -0.44
      rotation 0 0.7071062811861719 0.7071072811865696 3.14159
      children [
        Shape {
          appearance PBRAppearance {
            baseColor 0.2 0.2 0.2
            metalness 0
          }
          geometry DEF shelf_2 Box {
            size 0.2 0.125 0.02
          }
        }
      ]
      name "solid(20)"
      boundingObject USE shelf_2
    }
    DEF piston_2 SliderJoint {
      jointParameters JointParameters {
      }
      device [
        LinearMotor {
          name "piston 2"
          maxVelocity 0.1
        }
      ]
      endPoint Solid {
        translation 0.005 0.375 -0.48
        rotation 0 0.7071062811861719 0.7071072811865696 3.14159
        children [
          Shape {
            appearance PBRAppearance {
              baseColor 0.4 0.4 0.4
              metalness 0
            }
            geometry DEF piston_2 Box {
              size 0.04 0.02 0.07
            }
          }
        ]
        name "solid(18)"
        boundingObject USE piston_2
      }
    }
    DEF piston_1 SliderJoint {
      jointParameters JointParameters {
      }
      device [
        LinearMotor {
          name "piston 1"
          maxVelocity 0.1
        }
      ]
      endPoint Solid {
        translation -0.065 0.375 -0.48
        rotation 1 0 0 1.5708
        children [
          Shape {
            appearance PBRAppearance {
              baseColor 0.4 0.4 0.4
              metalness 0
            }
            geometry DEF piston_1 Box {
              size 0.04 0.02 0.07
            }
          }
        ]
        name "solid(17)"
        boundingObject USE piston_1
      }
    }
    PointLight {
      attenuation 0 0 1
      color 0.8 0.8 0.8
      intensity 0.1
      location 0 0.45 -0.35
    }
    DEF front_size_6 Solid {
      translation 0.1385 0.365 -0.3
      children [
        Shape {
          appearance PBRAppearance {
            baseColor 0.2 0.2 0.2
            metalness 0
          }
          geometry DEF front_size_6 Box {
            size 0.023 0.03 0.02
          }
        }
      ]
      name "solid(13)"
      boundingObject USE front_size_6
    }
    DEF front_size_9 Solid {
      translation 0.12 0.36 -0.285503
      rotation 2.3464099999870814e-06 0.9999999999944944 2.3464099999870814e-06 1.5708
      children [
        Shape {
          appearance PBRAppearance {
            baseColor 0.2 0.2 0.2
            metalness 0
          }
          geometry DEF front_size_9 Box {
            size 0.03 0.03 0.006
          }
        }
      ]
      name "solid(16)"
      boundingObject USE front_size_9
    }
    DEF front_size_8 Solid {
      translation 0.13 0.36 -0.285503
      rotation 2.3464099999870814e-06 0.9999999999944944 2.3464099999870814e-06 1.5708
      children [
        Shape {
          appearance PBRAppearance {
            baseColor 0.2 0.2 0.2
            metalness 0
          }
          geometry DEF front_size_8 Box {
            size 0.03 0.03 0.006
          }
        }
      ]
      name "solid(15)"
      boundingObject USE front_size_8
    }
    DEF front_size_7 Solid {
      translation 0.125 0.358 -0.272929
      rotation 1 0 0 1.0472
      children [
        Shape {
          appearance PBRAppearance {
            baseColor 0.2 0.2 0.2
            metalness 0
          }
          geometry DEF front_size_7 Box {
            size 0.015 0.05 0.01
          }
        }
      ]
      name "solid(14)"
      boundingObject USE front_size_7
    }
    DEF coin_slant_desk Solid {
      translation 0.13 0.33 -0.361838
      rotation 1 0 0 1.4
      children [
        Shape {
          appearance PBRAppearance {
            baseColor 0.2 0.2 0.2
            metalness 0
          }
          geometry DEF coin_slant_desk Box {
            size 0.04 0.12 0.02
          }
        }
      ]
      name "solid(23)"
      boundingObject USE coin_slant_desk
    }
    DEF coin_slant_desk_2 Solid {
      translation 0.13 0.275 -0.437273
      rotation 1 0 0 1.7
      children [
        Shape {
          appearance PBRAppearance {
            baseColor 0.2 0.2 0.2
            metalness 0
          }
          geometry DEF coin_slant_desk_2 Box {
            size 0.04 0.12 0.02
          }
        }
      ]
      name "solid(25)"
      boundingObject USE coin_slant_desk_2
    }
    DEF coin_slant_desk_3 Solid {
      translation 0.13 0.2 -0.361838
      rotation 1 0 0 1.4
      children [
        Shape {
          appearance PBRAppearance {
            baseColor 0.2 0.2 0.2
            metalness 0
          }
          geometry DEF coin_slant_desk_3 Box {
            size 0.04 0.12 0.04
          }
        }
      ]
      name "solid(24)"
      boundingObject USE coin_slant_desk_3
    }
    DEF front_size_5 Solid {
      translation 0.1115 0.365 -0.3
      children [
        Shape {
          appearance PBRAppearance {
            baseColor 0.2 0.2 0.2
            metalness 0
          }
          geometry DEF front_size_5 Box {
            size 0.023 0.03 0.02
          }
        }
      ]
      name "solid(12)"
      boundingObject USE front_size_5
    }
    DEF front_size_11 Solid {
      translation 0.1115 0.115 -0.3
      children [
        Shape {
          appearance PBRAppearance {
            baseColor 0.2 0.2 0.2
            metalness 0
          }
          geometry DEF front_size_11 Box {
            size 0.023 0.03 0.02
          }
        }
      ]
      name "solid(26)"
      boundingObject USE front_size_11
    }
    DEF front_size_12 Solid {
      translation 0.1385 0.115 -0.3
      children [
        Shape {
          appearance PBRAppearance {
            baseColor 0.2 0.2 0.2
            metalness 0
          }
          geometry DEF front_size_12 Box {
            size 0.023 0.03 0.02
          }
        }
      ]
      name "solid(32)"
      boundingObject USE front_size_12
    }
    DEF front_size_4 Solid {
      translation 0.125 0.415 -0.3
      children [
        Shape {
          appearance PBRAppearance {
            baseColor 0.2 0.2 0.2
            metalness 0
          }
          geometry DEF front_size_4 Box {
            size 0.05 0.07 0.02
          }
        }
      ]
      name "solid(9)"
      boundingObject USE front_size_4
    }
    DEF front_size_3 Solid {
      translation 0.125 0.24 -0.3
      children [
        Shape {
          appearance PBRAppearance {
            baseColor 0.2 0.2 0.2
            metalness 0
          }
          geometry DEF front_size_3 Box {
            size 0.05 0.22 0.02
          }
        }
      ]
      name "solid(8)"
      boundingObject USE front_size_3
    }
    DEF Glass Solid {
      translation 0.375 0.325 -0.3
      children [
        Shape {
          appearance PBRAppearance {
            transparency 0.993
            metalness 0
            emissiveColor 1 1 1
          }
          geometry DEF glass Box {
            size 0.2 0.25 0.02
          }
        }
      ]
      name "solid(7)"
      boundingObject USE glass
    }
    DEF bottom_size Solid {
      translation 0.025 0 -0.4
      rotation 1 0 0 -1.5707953071795862
      children [
        Shape {
          appearance PBRAppearance {
            baseColor 0.2 0.2 0.2
            metalness 0
          }
          geometry DEF bottom_size Box {
            size 0.25 0.2 0.01
          }
        }
      ]
      name "solid(6)"
      boundingObject USE bottom_size
    }
    DEF top_size Solid {
      translation 0.025 0.5 -0.4
      rotation 1 0 0 -1.5707953071795862
      children [
        Shape {
          appearance PBRAppearance {
            baseColor 0.2 0.2 0.2
            metalness 0
          }
          geometry DEF top_size Box {
            size 0.25 0.2 0.02
          }
        }
      ]
      name "solid(5)"
      boundingObject USE top_size
    }
    DEF front_size_2 Solid {
      translation 0.025 0.475 -0.3
      rotation 0 -1 0 0
      children [
        Shape {
          appearance PBRAppearance {
            baseColor 0.2 0.2 0.2
            metalness 0
          }
          geometry DEF front_size_2 Box {
            size 0.25 0.05 0.02
          }
        }
      ]
      name "solid(4)"
      boundingObject USE front_size_2
    }
    DEF front_size_10 Solid {
      translation 0 0.175 -0.3
      rotation 0 -1 0 0
      children [
        Shape {
          appearance PBRAppearance {
            baseColor 0.2 0.2 0.2
            metalness 0
          }
          geometry DEF front_size_10 Box {
            size 0.2 0.05 0.02
          }
        }
      ]
      name "solid(11)"
      boundingObject USE front_size_10
    }
    DEF front_size_1 Solid {
      translation 0.025 0.05 -0.3
      rotation 0 -1 0 0
      children [
        Shape {
          appearance PBRAppearance {
            baseColor 0.2 0.2 0.2
            metalness 0
          }
          geometry DEF front_size_1 Box {
            size 0.25 0.1 0.02
          }
        }
      ]
      name "solid(3)"
      boundingObject USE front_size_1
    }
    DEF right_size_glass Solid {
      translation 0.15 0.25 -0.4
      rotation 0 1 0 -1.5708003061004252
      children [
        Shape {
          appearance PBRAppearance {
            baseColor 0.2 0.2 0.2
            transparency 0.2
            metalness 0
          }
          geometry DEF right_size_glass Box {
            size 0.2 0.5 0.02
          }
        }
      ]
      name "solid(2)"
      boundingObject USE right_size_glass
    }
    DEF right_size_2 Solid {
      translation 0.11 0.25 -0.4
      rotation 0 1 0 -1.5708003061004252
      children [
        Shape {
          appearance PBRAppearance {
            baseColor 0.2 0.2 0.2
            metalness 0
          }
          geometry DEF right_size_2 Box {
            size 0.2 0.5 0.02
          }
        }
      ]
      name "solid(31)"
      boundingObject USE right_size_2
    }
    DEF left_size Solid {
      translation -0.1 0.25 -0.4
      rotation 0 1 0 -1.5708003061004252
      children [
        Shape {
          appearance PBRAppearance {
            baseColor 0.2 0.2 0.2
            metalness 0
          }
          geometry DEF left_size Box {
            size 0.2 0.5 0.02
          }
        }
      ]
      name "solid(1)"
      boundingObject USE left_size
    }
    DEF shelf_block_1 Solid {
      translation -0.03 0.325 -0.44
      rotation 0 1 0 -1.5708003061004252
      children [
        Shape {
          appearance PBRAppearance {
            baseColor 0.2 0.2 0.2
            metalness 0
          }
          geometry DEF shelf_block_1 Box {
            size 0.125 0.2 0.02
          }
        }
      ]
      name "solid(21)"
      boundingObject USE shelf_block_1
    }
    DEF shelf_block_2 Solid {
      translation 0.04 0.325 -0.44
      rotation 0 1 0 -1.5708003061004252
      children [
        Shape {
          appearance PBRAppearance {
            baseColor 0.2 0.2 0.2
            metalness 0
          }
          geometry DEF shelf_block_2 Box {
            size 0.125 0.2 0.02
          }
        }
      ]
      name "solid(22)"
      boundingObject USE shelf_block_2
    }
    DEF back_size Solid {
      translation 0.025 0.25 -0.5
      children [
        Shape {
          appearance PBRAppearance {
            baseColor 0.2 0.2 0.2
            metalness 0
          }
          geometry DEF back_size Box {
            size 0.25 0.5 0.02
          }
        }
      ]
      boundingObject USE back_size
    }
    DEF slant_desk Solid {
      translation 0.025 0.065 -0.401207
      rotation 1 0 0 0.15
      children [
        Shape {
          appearance PBRAppearance {
            baseColor 0.2 0.2 0.2
            metalness 0
          }
          geometry DEF slant_desk Box {
            size 0.25 0.1 0.2
          }
        }
      ]
      name "solid(10)"
      boundingObject USE slant_desk
    }
  ]
  controller "vydejni_automat"
}
DEF red_coin Solid {
  translation 0.125 0.025 -0.25
  rotation 0.5773489358533613 0.5773489358533613 0.5773529358529169 -2.0944003061004253
  children [
    Shape {
      appearance PBRAppearance {
        baseColor 1 0 0
        metalness 0
      }
      geometry DEF cylinder_geom Cylinder {
        height 0.003
        radius 0.01
      }
    }
  ]
  name "solid(17)"
  boundingObject USE cylinder_geom
  physics Physics {
  }
}
DEF yellow_coin Solid {
  translation 0.125 0.0215 -0.22
  rotation 0.5773482691863839 0.5773502691873165 0.5773522691882489 -2.094395307179586
  children [
    Shape {
      appearance PBRAppearance {
        baseColor 1 1 0
        metalness 0
      }
      geometry DEF yellow_coin Cylinder {
        height 0.003
        radius 0.01
      }
    }
  ]
  boundingObject USE yellow_coin
  physics Physics {
  }
}
DEF blue_coin Solid {
  translation 0.125 0.025 -0.28
  rotation 0.577349935856137 0.577349935856137 0.5773509358560258 -2.094395307179586
  children [
    Shape {
      appearance PBRAppearance {
        baseColor 0 0.1 1
        metalness 0
      }
      geometry DEF blue_coin Cylinder {
        height 0.003
        radius 0.01
      }
    }
  ]
  name "solid(1)"
  boundingObject USE blue_coin
  physics Physics {
  }
}
