#VRML_SIM R2020b utf8
WorldInfo {
  coordinateSystem "NUE"
  contactProperties [
    ContactProperties {
      softCFM 0.0001
    }
  ]
}
Viewpoint {
  orientation 0.47288265161553655 0.8734536860927138 0.11602006745434254 5.687163796032783
  position -0.7121668217927688 0.7101303548082283 1.0227388743742432
}
TexturedBackground {
}
TexturedBackgroundLight {
}
RectangleArena {
  floorSize 1.5 1.5
  wallHeight 0.2
}
DEF Automat Robot {
  translation 0 0.01 0
  rotation 1 0 0 0
  children [
    DEF shelf_1 Solid {
      translation -0.0199992 0.33 -0.44
      rotation 0 0.7071062811861719 0.7071072811865696 3.14159
      children [
        Shape {
          appearance PBRAppearance {
            baseColor 0.2 0.2 0.2
            metalness 0
          }
          geometry DEF shelf_1 Box {
            size 0.25 0.1 0.01
          }
        }
      ]
      name "solid(19)"
      boundingObject USE shelf_1
    }
    DEF shelf_2 Solid {
      translation -0.0199992 0.24 -0.44
      rotation 0 0.7071062811861719 0.7071072811865696 3.14159
      children [
        Shape {
          appearance PBRAppearance {
            baseColor 0.2 0.2 0.2
            metalness 0
          }
          geometry DEF shelf_2 Box {
            size 0.25 0.1 0.01
          }
        }
      ]
      name "solid(20)"
      boundingObject USE shelf_2
    }
    DEF piston_2 SliderJoint {
      jointParameters JointParameters {
      }
      device [
        LinearMotor {
          name "piston 2"
          maxVelocity 0.1
        }
      ]
      endPoint Solid {
        translation 0.045 0.37 -0.48
        rotation 0 0.7071062811861719 0.7071072811865696 3.14159
        children [
          Shape {
            appearance PBRAppearance {
              baseColor 0.4 0.4 0.4
              metalness 0
            }
            geometry DEF piston_2 Box {
              size 0.05 0.01 0.05
            }
          }
        ]
        name "solid(18)"
        boundingObject USE piston_2
      }
    }
    DEF piston_1 SliderJoint {
      jointParameters JointParameters {
      }
      device [
        LinearMotor {
          name "piston 1"
          maxVelocity 0.1
        }
      ]
      endPoint Solid {
        translation -0.09 0.37 -0.48
        rotation 1 0 0 1.5708
        children [
          Shape {
            appearance PBRAppearance {
              baseColor 0.4 0.4 0.4
              metalness 0
            }
            geometry DEF piston_1 Box {
              size 0.05 0.01 0.05
            }
          }
        ]
        name "solid(17)"
        boundingObject USE piston_1
      }
    }
    PointLight {
      attenuation 0 0 1
      color 0.8 0.8 0.8
      intensity 0.1
      location 0 0.45 -0.35
    }
    DEF front_size_6 Solid {
      translation 0.1385 0.365 -0.3
      children [
        Shape {
          appearance PBRAppearance {
            baseColor 0.2 0.2 0.2
            metalness 0
          }
          geometry DEF front_size_6 Box {
            size 0.023 0.03 0.01
          }
        }
      ]
      name "solid(13)"
      boundingObject USE front_size_6
    }
    DEF front_size_9 Solid {
      translation 0.12 0.36 -0.285503
      rotation 2.3464099999870814e-06 0.9999999999944944 2.3464099999870814e-06 1.5708
      children [
        Shape {
          appearance PBRAppearance {
            baseColor 0.2 0.2 0.2
            metalness 0
          }
          geometry DEF front_size_9 Box {
            size 0.03 0.03 0.005
          }
        }
      ]
      name "solid(16)"
      boundingObject USE front_size_9
    }
    DEF front_size_8 Solid {
      translation 0.13 0.36 -0.285503
      rotation 2.3464099999870814e-06 0.9999999999944944 2.3464099999870814e-06 1.5708
      children [
        Shape {
          appearance PBRAppearance {
            baseColor 0.2 0.2 0.2
            metalness 0
          }
          geometry DEF front_size_8 Box {
            size 0.03 0.03 0.005
          }
        }
      ]
      name "solid(15)"
      boundingObject USE front_size_8
    }
    DEF front_size_7 Solid {
      translation 0.125 0.364071 -0.277929
      rotation 1 0 0 0.785398
      children [
        Shape {
          appearance PBRAppearance {
            baseColor 0.2 0.2 0.2
            metalness 0
          }
          geometry DEF front_size_7 Box {
            size 0.01 0.05 0.005
          }
        }
      ]
      name "solid(14)"
      boundingObject USE front_size_7
    }
    DEF front_size_5 Solid {
      translation 0.1115 0.365 -0.3
      children [
        Shape {
          appearance PBRAppearance {
            baseColor 0.2 0.2 0.2
            metalness 0
          }
          geometry DEF front_size_5 Box {
            size 0.023 0.03 0.01
          }
        }
      ]
      name "solid(12)"
      boundingObject USE front_size_5
    }
    DEF front_size_4 Solid {
      translation 0.125 0.415 -0.3
      children [
        Shape {
          appearance PBRAppearance {
            baseColor 0.2 0.2 0.2
            metalness 0
          }
          geometry DEF front_size_4 Box {
            size 0.05 0.07 0.01
          }
        }
      ]
      name "solid(9)"
      boundingObject USE front_size_4
    }
    DEF front_size_3 Solid {
      translation 0.125 0.225 -0.3
      children [
        Shape {
          appearance PBRAppearance {
            baseColor 0.2 0.2 0.2
            metalness 0
          }
          geometry DEF front_size_3 Box {
            size 0.05 0.25 0.01
          }
        }
      ]
      name "solid(8)"
      boundingObject USE front_size_3
    }
    DEF Glass Solid {
      translation -0.025 0.325 -0.3
      children [
        Shape {
          appearance PBRAppearance {
            transparency 0.993
            metalness 0
            emissiveColor 1 1 1
          }
          geometry DEF glass Box {
            size 0.25 0.25 0.01
          }
        }
      ]
      name "solid(7)"
      boundingObject USE glass
    }
    DEF bottom_size Solid {
      translation 0 0 -0.4
      rotation 1 0 0 -1.5707953071795862
      children [
        Shape {
          appearance PBRAppearance {
            baseColor 0.2 0.2 0.2
            metalness 0
          }
          geometry DEF bottom_size Box {
            size 0.3 0.2 0.01
          }
        }
      ]
      name "solid(6)"
      boundingObject USE bottom_size
    }
    DEF top_size Solid {
      translation 0 0.5 -0.4
      rotation 1 0 0 -1.5707953071795862
      children [
        Shape {
          appearance PBRAppearance {
            baseColor 0.2 0.2 0.2
            metalness 0
          }
          geometry DEF top_size Box {
            size 0.3 0.2 0.01
          }
        }
      ]
      name "solid(5)"
      boundingObject USE top_size
    }
    DEF front_size_2 Solid {
      translation 0 0.475 -0.3
      rotation 0 -1 0 0
      children [
        Shape {
          appearance PBRAppearance {
            baseColor 0.2 0.2 0.2
            metalness 0
          }
          geometry DEF front_size_2 Box {
            size 0.3 0.05 0.01
          }
        }
      ]
      name "solid(4)"
      boundingObject USE front_size_2
    }
    DEF front_size_10 Solid {
      translation -0.025 0.175 -0.3
      rotation 0 -1 0 0
      children [
        Shape {
          appearance PBRAppearance {
            baseColor 0.2 0.2 0.2
            metalness 0
          }
          geometry DEF front_size_10 Box {
            size 0.25 0.05 0.01
          }
        }
      ]
      name "solid(11)"
      boundingObject USE front_size_10
    }
    DEF front_size_1 Solid {
      translation 0 0.05 -0.3
      rotation 0 -1 0 0
      children [
        Shape {
          appearance PBRAppearance {
            baseColor 0.2 0.2 0.2
            metalness 0
          }
          geometry DEF front_size_1 Box {
            size 0.3 0.1 0.01
          }
        }
      ]
      name "solid(3)"
      boundingObject USE front_size_1
    }
    DEF right_size Solid {
      translation 0.15 0.25 -0.4
      rotation 0 1 0 -1.5708003061004252
      children [
        Shape {
          appearance PBRAppearance {
            baseColor 0.2 0.2 0.2
            metalness 0
          }
          geometry DEF right_size Box {
            size 0.2 0.5 0.01
          }
        }
      ]
      name "solid(2)"
      boundingObject USE right_size
    }
    DEF left_size Solid {
      translation -0.15 0.25 -0.4
      rotation 0 1 0 -1.5708003061004252
      children [
        Shape {
          appearance PBRAppearance {
            baseColor 0.2 0.2 0.2
            metalness 0
          }
          geometry DEF left_size Box {
            size 0.2 0.5 0.01
          }
        }
      ]
      name "solid(1)"
      boundingObject USE left_size
    }
    DEF back_size Solid {
      translation 0 0.25 -0.5
      children [
        Shape {
          appearance PBRAppearance {
            baseColor 0.2 0.2 0.2
            metalness 0
          }
          geometry DEF back_size Box {
            size 0.3 0.5 0.01
          }
        }
      ]
      boundingObject USE back_size
    }
    DEF slant_desk Solid {
      translation 0 0.114891 -0.396725
      rotation 1 0 0 0.261799
      children [
        Shape {
          appearance PBRAppearance {
            baseColor 0.2 0.2 0.2
            metalness 0
          }
          geometry DEF slant_desk Box {
            size 0.3 0.01 0.2
          }
        }
      ]
      name "solid(10)"
      boundingObject USE slant_desk
    }
  ]
  controller "vydejni_automat"
}
DEF red_coin Solid {
  translation 0.00500206 0.0015 -0.03
  children [
    Shape {
      appearance PBRAppearance {
        baseColor 1 0 0
        metalness 0
      }
      geometry DEF cylinder_geom Cylinder {
        height 0.003
        radius 0.01
      }
    }
  ]
  name "solid(17)"
  boundingObject USE cylinder_geom
  physics Physics {
  }
}
DEF yellow_coin Solid {
  translation 0.00499839 0.0115 0.0200001
  rotation 0.5773482691863839 0.5773502691873165 0.5773522691882489 -2.094395307179586
  children [
    Shape {
      appearance PBRAppearance {
        baseColor 1 1 0
        metalness 0
      }
      geometry DEF yellow_coin Cylinder {
        height 0.003
        radius 0.01
      }
    }
  ]
  boundingObject USE yellow_coin
  physics Physics {
  }
}
DEF blue_coin Solid {
  translation 0.04 0.0015 0
  children [
    Shape {
      appearance PBRAppearance {
        baseColor 0 0.1 1
        metalness 0
      }
      geometry DEF blue_coin Cylinder {
        height 0.003
        radius 0.01
      }
    }
  ]
  name "solid(1)"
  boundingObject USE blue_coin
  physics Physics {
  }
}
